[32mINFO    [0m pytest_operator.plugin:plugin.py:862 Model status:

Model  Controller          Cloud/Region        Version  SLA          Timestamp
test   microk8s-localhost  microk8s/localhost  3.1.8    unsupported  02:31:29Z

App                  Version  Status   Scale  Charm                Channel      Rev  Address         Exposed  Message
postgresql-k8s       14.11    waiting      3  postgresql-k8s       14/edge      271  10.152.183.198  no       installing agent
postgresql-test-app           active       1  postgresql-test-app  latest/edge  145  10.152.183.240  no       

Unit                    Workload  Agent      Address       Ports  Message
postgresql-k8s/0*       waiting   executing  10.1.236.141         awaiting for cluster to start
postgresql-k8s/1        unknown   idle       10.1.236.140         
postgresql-k8s/2        unknown   idle       10.1.236.142         
postgresql-test-app/0*  active    idle       10.1.236.136         

[32mINFO    [0m pytest_operator.plugin:plugin.py:868 Juju error logs:

unit-postgresql-k8s-0: 02:22:14 ERROR unit.postgresql-k8s/0.juju-log Uncaught exception while in charm code:
Traceback (most recent call last):
  File "/var/lib/juju/agents/unit-postgresql-k8s-0/charm/./src/charm.py", line 1691, in <module>
    main(PostgresqlOperatorCharm, use_juju_for_storage=True)
  File "/var/lib/juju/agents/unit-postgresql-k8s-0/charm/venv/ops/main.py", line 544, in main
    manager.run()
  File "/var/lib/juju/agents/unit-postgresql-k8s-0/charm/venv/ops/main.py", line 520, in run
    self._emit()
  File "/var/lib/juju/agents/unit-postgresql-k8s-0/charm/venv/ops/main.py", line 509, in _emit
    _emit_charm_event(self.charm, self.dispatcher.event_name)
  File "/var/lib/juju/agents/unit-postgresql-k8s-0/charm/venv/ops/main.py", line 143, in _emit_charm_event
    event_to_emit.emit(*args, **kwargs)
  File "/var/lib/juju/agents/unit-postgresql-k8s-0/charm/venv/ops/framework.py", line 352, in emit
    framework._emit(event)
  File "/var/lib/juju/agents/unit-postgresql-k8s-0/charm/venv/ops/framework.py", line 851, in _emit
    self._reemit(event_path)
  File "/var/lib/juju/agents/unit-postgresql-k8s-0/charm/venv/ops/framework.py", line 941, in _reemit
    custom_handler(event)
  File "/var/lib/juju/agents/unit-postgresql-k8s-0/charm/./src/charm.py", line 755, in _on_postgresql_pebble_ready
    self._update_pebble_layers()
  File "/var/lib/juju/agents/unit-postgresql-k8s-0/charm/./src/charm.py", line 1594, in _update_pebble_layers
    container.replan()
  File "/var/lib/juju/agents/unit-postgresql-k8s-0/charm/venv/ops/model.py", line 2129, in replan
    self._pebble.replan_services()
  File "/var/lib/juju/agents/unit-postgresql-k8s-0/charm/venv/ops/pebble.py", line 1905, in replan_services
    return self._services_action('replan', [], timeout, delay)
  File "/var/lib/juju/agents/unit-postgresql-k8s-0/charm/venv/ops/pebble.py", line 1989, in _services_action
    raise ChangeError(change.err, change)
ops.pebble.ChangeError: cannot perform the following tasks:
- Start service "postgresql" (cannot start service: fork/exec /usr/bin/patroni: exec format error)
----- Logs from task 0 -----
2024-06-08T02:22:14Z ERROR cannot start service: fork/exec /usr/bin/patroni: exec format error
-----
unit-postgresql-k8s-0: 02:22:14 ERROR juju.worker.uniter.operation hook "postgresql-pebble-ready" (via hook dispatching script: dispatch) failed: exit status 1
unit-postgresql-k8s-0: 02:22:14 ERROR juju.worker.uniter pebble poll failed for container "postgresql": failed to send pebble-ready event: hook failed

[32mINFO    [0m pytest_operator.plugin:plugin.py:947 Forgetting model main...